2025-08-31 13:21:31,143 - WARNING - AuthService: User with credentials: test tried to login with wrong password.
Traceback (most recent call last):
  File "E:\programming\SocialNetwork\backend\exceptions\exceptions_handler.py", line 46, in wrapper
    return await func(*args, **kwargs)
           ^^^^^^^^^^^^^^^^^^^^^^^^^^^
  File "E:\programming\SocialNetwork\backend\services\core_services\main_services\main_auth_service.py", line 68, in login
    raise Unauthorized(detail=f"AuthService: User with credentials: {credentials.username} tried to login with wrong password.", client_safe_detail="Password didn't match")
exceptions.custom_exceptions.Unauthorized: AuthService: User with credentials: test tried to login with wrong password.

The above exception was the direct cause of the following exception:

Traceback (most recent call last):
  File "E:\programming\SocialNetwork\backend\exceptions\exceptions_handler.py", line 21, in wrapper
    return await func(*args, **kwargs)
           ^^^^^^^^^^^^^^^^^^^^^^^^^^^
  File "E:\programming\SocialNetwork\backend\routes\auth_router.py", line 29, in login
    response = await auth.login(credentials=credentials)
               ^^^^^^^^^^^^^^^^^^^^^^^^^^^^^^^^^^^^^^^^^
  File "E:\programming\SocialNetwork\backend\exceptions\exceptions_handler.py", line 52, in wrapper
    raise UnauthorizedExc(client_safe_detail=e.client_safe_detail, dev_log_detail=str(e), exc_type=e) from e
exceptions.custom_exceptions.UnauthorizedExc: AuthService: User with credentials: test tried to login with wrong password.
